Workbook

Sheet Test Plan
A1: Section | B1: Details
A2: Project name | B2: Guru99 Banking project
A3: Document | B3: Test plan
A4: SRS version | B4: 2
A5: Testing type | B5: Manual functional testing
A6: Objective | B6: Verify that Guru99 Bank meets the specified functional requirements
A7: Scope | B7: Functional testing and external interfaces
A8: Out of scope | B8: Automation testing and performance/stress testing
A9: Roles | B9: Manager and customer
A10: Test environment | B10: Browser, OS
A11: Test data | B11: Customer, account, login and transaction data
A12: Entry criteria | B12: Requirements available and test environment accessible
A13: Exit criteria | B13: Planned test cases executed and defects documented
A14: Deliverables | B14: Test cases, bug report, RTM, test execution, summary report
A15: Test approach | B15: Black-box manual testing using requirement-based testing, equivalence partitioning, boundary value analysis, positive and negative testing and error guessing
A16: Test levels | B16: System testing of each module through the web interface
... A23: Risks and assumptions | B23: The application is a shared public demo site that may change, show errors or lose data; results depend on its behavior at the time of execution

Sheet Test Scenarios
A1: Scenario ID | B1: Scenario | C1: Req | D1: Test Cases
A2: SC_LG_01 | B2: Successful login as Manager | C2: 3.1.1 | D2: TC_LG_001
A3: SC_LG_02 | B3: Successful login as Customer | C3: 3.1.1 | D3: -
A4: SC_LG_03 | B4: Empty fields (User ID / Password / both) | C4: L1, L2 | D4: TC_LG_002 - TC_LG_004
A5: SC_LG_04 | B5: Invalid credentials (User ID or Password) | C5: L3 | D5: TC_LG_005 - TC_LG_006
A6: SC_LG_05 | B6: Case sensitivity of the credentials | C6: 3.1.1 | D6: TC_LG_007 - TC_LG_008
A7: SC_LG_06 | B7: Account lockout after 3 failed attempts | C7: L4, L5 | D7: TC_LG_009
A8: SC_LG_07 | B8: Login blocked for a locked account, even with valid credentials | C8: L4 | D8: TC_LG_010
A9: SC_LG_08 | B9: Reset button behavior | C9: 3.1.1 | D9: TC_LG_011
A10: SC_LG_09 | B10: Field properties (password masking, 30-character limit, spaces, special characters) | C10: 3.1.1 | D10: TC_LG_012 - TC_LG_013, TC_LG_015
A11: SC_LG_10 | B11: Logout and session termination | C11: 2.0 | D11: TC_LG_016 - TC_LG_017
A12: SC_LG_11 | B12: Session timeout after 15 minutes of inactivity | C12: 2.1.4 / E54 | D12: -
... A111: SC_CP_08 | B111: Security input (SQL injection) | C111: General | D111: TC_CP_023

Sheet Test Cases
A1: ID | B1: Title | C1: Description | D1: Pre-Condition | E1: Test steps | F1: Test data | G1: Priority | H1: Expected Result | I1: Actual result | J1: Status | K1: Designer | L1: Executer
A2: TC_LG_001 | B2: Successful login as Manager | C2: Verify that a Manager can log in with valid credentials | D2: Manager account exists and is active; Login page is open in Chrome | E2: 1. Enter User ID 2. Enter Password 3. Click Submit | F2: User ID: mngr668217 Password: rUqyzUv | G2: High | H2: User is redirected to the Manager Dashboard, and all Manager modules are displayed | I2: The manager was redirected to the Manager dashboard. | J2: Pass | K2: Amjad | L2: Amjad
A3: TC_LG_002 | B3: Empty User ID | C3: Verify that login is blocked when User ID is empty | D3: Login page is open | E3: 1. Leave User ID empty 2. Enter Password 3. Click Submit | F3: User ID: Password: rUqyzUv | G3: High | H3: E1: "User ID must not be blank" is displayed; login is not allowed | I3: The error message "User ID must not be blank" was displayed. | J3: Pass | K3: Amjad | L3: Amjad
A4: TC_LG_003 | B4: Empty Password | C4: Verify that login is blocked when Password is empty | D4: Login page is open | E4: 1. Enter User ID 2. Leave Password empty 3. Click Submit | F4: User ID: mngr668217 Password: | G4: High | H4: E2: "Password must not be blank" is displayed; login is not allowed | I4: The error message "Password must not be blank" was displayed. | J4: Pass | K4: Amjad | L4: Amjad
A5: TC_LG_004 | B5: Both fields empty | C5: Verify validation messages when both fields are empty | D5: Login page is open | E5: 1. Leave both fields empty 2. Click Submit | F5: User ID: Password: | G5: High | H5: E1 and E2 are displayed; login is not allowed | I5: The error messages "User ID must not be blank" and "Password must not be blank" were displayed. | J5: Pass | K5: Amjad | L5: Amjad
A6: TC_LG_005 | B6: Non-existent User ID | C6: Verify that an unregistered User ID is rejected | D6: Login page is open; the User ID does not exist in the system | E6: 1. Enter an unregistered User ID 2. Enter any Password 3. Click Submit | F6: User ID: ghost999 Password: Pass@123 | G6: High | H6: E3: "User ID and Password do not match" is displayed | I6: The alert "User is not valid" was displayed instead of the message required by the SRS (E3: "User ID and Password do not match"). The login was rejected. | J6: Fail | K6: Amjad | L6: Amjad
A7: TC_LG_006 | B7: Incorrect Password | C7: Verify that a valid User ID with a wrong Password is rejected | D7: Manager account exists and is active | E7: 1. Enter a valid User ID 2. Enter an incorrect Password 3. Click Submit | F7: User ID: mngr668217 Password: wrongpas | G7: High | H7: E3 is displayed; login is not allowed | I7: The alert "User is not valid" was displayed instead of the message required by the SRS (E3: "User ID and Password do not match"). The login was rejected. | J7: Fail | K7: Amjad | L7: Amjad
A8: TC_LG_007 | B8: Case sensitivity: User ID | C8: Verify that the User ID is case-sensitive | D8: Manager account "mngr668217" exists | E8: 1. Enter the User ID in uppercase 2. Enter the correct Password 3. Click Submit | F8: User ID: MNGR668217 Password: rUqyzUv | G8: Medium | H8: E3 is displayed (login rejected) | I8: The system accepted the User ID in uppercase and redirected the manager to the dashboard (the User ID is not case-sensitive). | J8: Fail | K8: Amjad | L8: Amjad
A9: TC_LG_008 | B9: Case sensitivity: Password | C9: Verify that the Password is case-sensitive | D9: Manager account "mngr668217" exists with password "rUqyzUv" | E9: 1. Enter the correct User ID 2. Enter the Password with different casing 3. Click Submit | F9: User ID: mngr668217 Password: RUQYZUV | G9: Medium | H9: E3 is displayed (login rejected) | I9: The system accepted the Password with different letter casing and redirected the manager to the dashboard (the Password is not case-sensitive). | J9: Fail | K9: Amjad | L9: Amjad
A10: TC_LG_009 | B10: Lockout after 3 failed attempts | C10: Verify that the account is locked after 3 consecutive failed login attempts | D10: Manager account is active and not locked; failed-attempt counter is 0 | E10: 1. Enter valid User ID and wrong Password, click Submit 2. Repeat step 1 (2nd attempt) 3. Repeat step 1 (3rd attempt) | F10: User ID: mngr668217 Password: wrongpas (wrong password, 3 consecutive attempts) | G10: High | H10: Attempts 1 and 2: E3 is displayed. Attempt 3: the account is locked and E55 is displayed (SRS is unclear about the 3rd-attempt message) | I10: The account was not locked after the 3 failed attempts and no error message was displayed. | J10: Fail | K10: Amjad | L10: Amjad
A11: TC_LG_010 | B11: Locked account with valid credentials | C11: Verify that a locked account cannot log in even with correct credentials | D11: Account is locked (after TC_LG_009) | E11: 1. Enter valid User ID 2. Enter correct Password 3. Click Submit | F11: User ID: mngr668217 Password: rUqyzUv (valid password) | G11: High | H11: Login is rejected with the lockout message (E55) | I11: The account was not locked, so the lockout message (E55) was not displayed. | J11: Fail | K11: Amjad | L11: Amjad
A12: TC_LG_011 | B12: Reset button | C12: Verify that the Reset button clears the form | D12: Login page is open | E12: 1. Enter data in both fields 2. Click Reset | F12: User ID: mngr668217 Password: rUqyzUv | G12: Medium | H12: Both fields are cleared, and no error messages are displayed | I12: Both fields were cleared and no error message was displayed. | J12: Pass | K12: Amjad | L12: Amjad
... A19: TC_LG_018 | B19: Access without login | C19: Verify that protected pages require authentication | D19: User is not logged in; a valid internal page URL is available | E19: 1. Open an internal page URL directly in the browser | F19: Direct URL of an internal page | G19: High | H19: User is redirected to the Login page | I19: The system opened the protected page directly without any authentication. | J19: Fail | K19: Amjad | L19: Amjad
B20: New Customer
A21: TC_NC_001 | B21: Create customer with valid data | C21: Verify a customer is created with all valid fields | D21: 1. Logged in as Manager 2. New Customer page is open | E21: 1. Enter the values from Test data 2. Click Submit | F21: Customer Name: John Smith Gender: Male Date of Birth: 1990-05-15 Address: 12 Main Street City: Alexandria State: Alexandria PIN Code: 123456 Mobile Number: 5551234567 Email: john.smith01@test.com Password: Pass@123 | G21: High | H21: Customer is created; a unique Customer ID is generated and a confirmation is displayed | I21: The customer was created successfully. Generated Customer ID: 4073. | J21: Pass | K21: Amjad | L21: Amjad
A22: TC_NC_002 | B22: Form fields and buttons | C22: Verify all fields in SRS 3.1.2 exist | D22: 1. Logged in as Manager 2. New Customer page is open | E22: 1. Open the New Customer page 2. Review the form | F22: – | G22: Medium | H22: Customer Name, Gender (Male/Female radio), Date of Birth (date picker), Address (textarea), City, State, PIN Code, Mobile Number, Email, Password, Submit and Reset are present | I22: Customer Name, Gender (Male/Female radio), Date of Birth (date picker), Address (textarea), City, State, PIN Code, Mobile Number, Email, Password, Submit and Reset are present | J22: Pass | K22: Amjad | L22: Amjad
A23: TC_NC_003 | B23: Reset button | C23: Verify Reset clears the form | D23: 1. Logged in as Manager 2. New Customer page is open | E23: 1. Enter the values from Test data 2. Click Reset | F23: Customer Name: John Smith Gender: Male Date of Birth: 1990-05-15 Address: 12 Main Street City: Alexandria State: Alexandria PIN Code: 123456 Mobile Number: 5551234567 Email: john.smith03@test.com Password: Pass@123 | G23: Medium | H23: All fields are cleared, Gender is deselected, and no error is displayed | I23: All fields are cleared, Gender is deselected, and no error is displayed | J23: Pass | K23: Amjad | L23: Amjad
A24: TC_NC_004 | B24: Unique Customer ID | C24: Verify each new customer gets a different ID | D24: 1. Logged in as Manager 2. New Customer page is open | E24: 1. Create customer A using the Customer A values 2. Create customer B using the Customer B values | F24: Customer Name: John Smith Gender: Male Date of Birth: 1990-05-15 Address: 12 Main Street City: Alexandria State: Alexandria PIN Code: 123456 Mobile Number: 5551234567 Email: Customer A: john.smith04a@test.com Customer B: john.smith04b@test.com ◄ Password: Pass@123 | G24: High | H24: Two different Customer IDs are generated | I24: Both customers were created successfully. Generated Customer IDs: 4620 (customer A) and 78692 (customer B). | J24: Pass | K24: Amjad | L24: Amjad
A25: TC_NC_005 | B25: Created customer data is saved correctly | C25: Verify saved details via Edit Customer | D25: 1. Logged in as Manager 2. Customer created in TC_NC_001 (Customer ID 4073) | E25: 1. Open the Edit Customer page 2. Enter the generated Customer ID 3. Submit | F25: Customer ID: 4073 Values to compare (from TC_NC_001): Customer Name: John Smith Gender: Male Date of Birth: 1990-05-15 Address: 12 Main Street City: Alexandria State: Alexandria PIN Code: 123456 Mobile Number: 5551234567 Email: john.smith01@test.com Password: Pass@123 | G25: High | H25: All entered details (name, gender, DOB, address, city, state, PIN, mobile, email) match what was entered | I25: All entered details (name, gender, DOB, address, city, state, PIN, mobile, email) match what was entered | J25: Pass | K25: Amjad | L25: Amjad
A26: TC_NC_006 | B26: Name: blank (NC1) | C26: Verify blank name is rejected | D26: 1. Logged in as Manager 2. New Customer page is open | E26: 1. Leave Customer Name empty and enter the rest from Test data 2. Click Submit | F26: Customer Name: (empty) ◄ Gender: Male Date of Birth: 1990-05-15 Address: 12 Main Street City: Alexandria State: Alexandria PIN Code: 123456 Mobile Number: 5551234567 Email: john.smith06@test.com Password: Pass@123 | G26: High | H26: E4: "Customer Name must not be blank"; no customer created | I26: E4: "Customer Name must not be blank"; no customer created | J26: Pass | K26: Amjad | L26: Amjad
A27: TC_NC_007 | B27: Name: numbers (NC2) | C27: Verify numbers are rejected | D27: 1. Logged in as Manager 2. New Customer page is open | E27: 1. Enter the values from Test data 2. Click Submit | F27: Customer Name: John123 ◄ Gender: Male Date of Birth: 1990-05-15 Address: 12 Main Street City: Alexandria State: Alexandria PIN Code: 123456 Mobile Number: 5551234567 Email: john.smith07@test.com Password: Pass@123 | G27: High | H27: E48: "Numbers are not allowed" | I27: E48: "Numbers are not allowed" | J27: Pass | K27: Amjad | L27: Amjad
A28: TC_NC_008 | B28: Name: special characters (NC3) | C28: Verify special characters are rejected | D28: 1. Logged in as Manager 2. New Customer page is open | E28: 1. Enter the values from Test data 2. Click Submit | F28: Customer Name: John@#$ ◄ Gender: Male Date of Birth: 1990-05-15 Address: 12 Main Street City: Alexandria State: Alexandria PIN Code: 123456 Mobile Number: 5551234567 Email: john.smith08@test.com Password: Pass@123 | G28: High | H28: E46: "Special characters are not allowed" | I28: E46: "Special characters are not allowed" | J28: Pass | K28: Amjad | L28: Amjad
A29: TC_NC_009 | B29: Name: leading space (NC4) | C29: Verify a leading space is rejected | D29: 1. Logged in as Manager 2. New Customer page is open | E29: 1. Enter the values from Test data 2. Click Submit | F29: Customer Name: " John" (a space, then John) ◄ Gender: Male Date of Birth: 1990-05-15 Address: 12 Main Street City: Alexandria State: Alexandria PIN Code: 123456 Mobile Number: 5551234567 Email: john.smith09@test.com Password: Pass@123 | G29: Medium | H29: E47: "First character cannot be space" | I29: E47: "First character cannot be space" | J29: Pass | K29: Amjad | L29: Amjad
A30: TC_NC_010 | B30: Name: spaces between words | C30: Verify a valid multi-word name is accepted | D30: 1. Logged in as Manager 2. New Customer page is open | E30: 1. Enter the values from Test data 2. Click Submit | F30: Customer Name: Mary Ann Lee ◄ Gender: Male Date of Birth: 1990-05-15 Address: 12 Main Street City: Alexandria State: Alexandria PIN Code: 123456 Mobile Number: 5551234567 Email: john.smith10@test.com Password: Pass@123 | G30: Medium | H30: Customer is created successfully | I30: Customer is created successfully | J30: Pass | K30: Amjad | L30: Amjad
A31: TC_NC_011 | B31: Name: max length 50 (BVA) | C31: Verify the 50-character limit | D31: 1. Logged in as Manager 2. New Customer page is open | E31: 1. Enter the values of Attempt 1 from Test data, click Submit 2. Reopen the New Customer page, enter the values of Attempt 2, click Submit | F31: Customer Name: [Attempt 1] AbcdefghijAbcdefghijAbcdefghijAbcdefghijAbcdefghij (50 letters) [Attempt 2] AbcdefghijAbcdefghijAbcdefghijAbcdefghijAbcdefghijk (51 letters) ◄ Gender: Male Date of Birth: 1990-05-15 Address: 12 Main Street City: Alexandria State: Alexandria PIN Code: 123456 Mobile Number: 5551234567 Email: [Attempt 1] john.smith11a@test.com [Attempt 2] john.smith11b@test.com Password: Pass@123 | G31: Medium | H31: 50 characters are accepted; the 51st is rejected or truncated | I31: The Customer Name field accepts a maximum of 25 characters. | J31: Fail | K31: Amjad | L31: Amjad
A32: TC_NC_012 | B32: Gender: not selected (NC20) | C32: Verify Gender is mandatory | D32: 1. Logged in as Manager 2. New Customer page is open | E32: 1. Leave Gender unselected and enter the rest from Test data 2. Click Submit | F32: Customer Name: John Smith Gender: (none selected) ◄ Date of Birth: 1990-05-15 Address: 12 Main Street City: Alexandria State: Alexandria PIN Code: 123456 Mobile Number: 5551234567 Email: john.smith12@test.com Password: Pass@123 | G32: High | H32: An error is displayed and no customer is created (message not defined in SRS) | I32: A gender was selected by default, so the Gender field cannot be left unselected. | J32: Fail | K32: Amjad | L32: Amjad
... A72: TC_NC_052 | B72: Double submission | C72: Verify no duplicate customer is created | D72: 1. Logged in as Manager 2. New Customer page is open | E72: 1. Enter the values from Test data 2. Double-click Submit quickly | F72: Customer Name: John Smith Gender: Male Date of Birth: 1990-05-15 Address: 12 Main Street City: Alexandria State: Alexandria PIN Code: 123456 Mobile Number: 5551234567 Email: john.smith52@test.com Password: Pass@123 | G72: Medium | H72: Only one customer is created; the duplicate attempt is ignored or rejected (E49) | I72: Only one customer is created; the duplicate attempt is ignored or rejected (E49) | J72: Pass | K72: Amjad | L72: Amjad
B73: Edit Customer
A74: TC_EC_001 | B74: Retrieve customer with valid ID | C74: Verify customer details are displayed for a valid Customer ID | D74: 1. Logged in as Manager 2. Customer 4073 exists and is associated with this Manager (created in TC_NC_001 and not yet edited) 3. Edit Customer page is open | E74: 1. Enter the Customer ID from Test data 2. Click Submit | F74: Customer ID: 4073 Values entered in TC_NC_001: Customer Name: John Smith Gender: Male Date of Birth: 1990-05-15 Address: 12 Main Street City: Alexandria State: Alexandria PIN Code: 123456 Mobile Number: 5551234567 Email: john.smith01@test.com | G74: High | H74: Customer details are displayed in an editable form and match the values entered at creation | I74: Customer details are displayed in an editable form and match the values entered at creation | J74: Pass | K74: Amjad | L74: Amjad
A75: TC_EC_002 | B75: Non-editable fields are disabled | C75: Verify Customer ID, Customer Name, Gender and Date of Birth cannot be edited | D75: 1. Logged in as Manager 2. Customer 4073 exists and is associated with this Manager (created in TC_NC_001) 3. Edit Customer page is open | E75: 1. Load customer 4073 2. Try to type in / change Customer ID, Customer Name, Gender and Date of Birth | F75: Customer ID: 4073 | G75: High | H75: Customer ID, Customer Name, Gender and Date of Birth are disabled and cannot be changed | I75: Customer ID, Customer Name, Gender and Date of Birth are disabled and cannot be changed | J75: Pass | K75: Amjad | L75: Amjad
A76: TC_EC_003 | B76: Editable fields are enabled | C76: Verify Address, City, State, PIN, Mobile and Email can be edited | D76: 1. Logged in as Manager 2. Customer 4073 exists and is associated with this Manager (created in TC_NC_001) 3. Edit Customer page is open | E76: 1. Load customer 4073 2. Click into each of the six fields and type | F76: Customer ID: 4073 | G76: High | H76: Address, City, State, PIN Code, Mobile Number and Email accept input | I76: Address, City, State, PIN Code, Mobile Number and Email accept input | J76: Pass | K76: Amjad | L76: Amjad
A77: TC_EC_004 | B77: Customer ID: blank (EC1) | C77: Verify blank Customer ID is rejected | D77: 1. Logged in as Manager 2. Edit Customer page is open | E77: 1. Leave Customer ID empty 2. Click Submit | F77: Customer ID: (empty) ◄ | G77: High | H77: E15: "Customer ID must not be blank" | I77: E15: "Customer ID must not be blank" | J77: Pass | K77: Amjad | L77: Amjad
A78: TC_EC_005 | B78: Customer ID: non-numeric (EC2) | C78: Verify letters and symbols are rejected | D78: 1. Logged in as Manager 2. Edit Customer page is open | E78: 1. Enter the Attempt 1 value, click Submit 2. Repeat for the Attempt 2 value | F78: Customer ID: [Attempt 1] ABC123 [Attempt 2] 12@#45 ◄ | G78: High | H78: E16: "Customer ID must be numeric" for each attempt | I78: E16: "Customer ID must be numeric" for each attempt | J78: Pass | K78: Amjad | L78: Amjad
A79: TC_EC_006 | B79: Customer ID: unusual numeric values | C79: Verify zero, negative and decimal values are handled | D79: 1. Logged in as Manager 2. Edit Customer page is open | E79: 1. Enter the Attempt 1 value, click Submit 2. Repeat for each remaining attempt | F79: Customer ID: [Attempt 1] 0 [Attempt 2] -5 [Attempt 3] 12.5 ◄ | G79: Low | H79: Each value is rejected with E16 or the "Customer ID does not exist" error; no customer is loaded | I79: Each value is rejected with E16 or the "Customer ID does not exist" error; no customer is loaded | J79: Pass | K79: Amjad | L79: Amjad
A80: TC_EC_007 | B80: Customer ID: does not exist (EC3) | C80: Verify an unknown Customer ID is rejected | D80: 1. Logged in as Manager 2. Edit Customer page is open | E80: 1. Enter a non-existent ID 2. Click Submit | F80: Customer ID: 999999999 ◄ | G80: High | H80: E51: "Customer ID does not exist" | I80: E51: "Customer ID does not exist" | J80: Pass | K80: Amjad | L80: Amjad
A81: TC_EC_008 | B81: Customer of another Manager (EC4) | C81: Verify a Manager cannot edit a customer associated with another Manager | D81: 1. A second Manager account exists 2. Customer 4073 is associated with Manager 1 only 3. Logged in as Manager 2 | E81: 1. Log in as Manager 2 2. Open Edit Customer 3. Enter the Customer ID of customer 4073, click Submit | F81: Customer ID: 4073 ◄ Logged in as: Manager 2 (a different Manager) | G81: High | H81: E44 is displayed; the customer details are not loaded | I81: E44 is displayed; the customer details are not loaded | J81: Pass | K81: Amjad | L81: Amjad
A82: TC_EC_009 | B82: Customer ID: SQL injection | C82: Verify basic SQL input is handled safely | D82: 1. Logged in as Manager 2. Edit Customer page is open | E82: 1. Enter the value from Test data 2. Click Submit | F82: Customer ID: 1 OR 1=1 ◄ | G82: Medium | H82: Input is rejected (E16); no customer data is returned and no database error is displayed | I82: Input is rejected (E16); no customer data is returned and no database error is displayed | J82: Pass | K82: Amjad | L82: Amjad
A83: TC_EC_010 | B83: Update all editable fields with valid data | C83: Verify all six editable fields can be updated together | D83: 1. Logged in as Manager 2. Customer 4073 exists and is associated with this Manager (created in TC_NC_001) 3. Edit Customer page is open | E83: 1. Enter the Customer ID from Test data and click Submit 2. Change the field(s) marked ◄ to the values in Test data 3. Click Submit | F83: Customer ID: 4073 Address: 45 Park Avenue ◄ City: Cairo ◄ State: Cairo ◄ PIN Code: 654321 ◄ Mobile Number: 5559876543 ◄ Email: john.edit10@test.com ◄ | G83: High | H83: Customer is updated successfully and a confirmation is displayed (message not defined in SRS) | I83: The customer data was updated, but no success message was displayed and the system redirected the manager to an empty white page. | J83: Fail | K83: Amjad | L83: Amjad
A84: TC_EC_011 | B84: Updated data is persisted | C84: Verify the update is saved by reloading the customer | D84: 1. Logged in as Manager 2. Customer 4073 exists and is associated with this Manager (updated in TC_EC_010) 3. Edit Customer page is open | E84: 1. Enter the Customer ID, click Submit 2. Compare the loaded values with the Test data | F84: Customer ID: 4073 Expected values (from TC_EC_010): Address: 45 Park Avenue City: Cairo State: Cairo PIN Code: 654321 Mobile Number: 5559876543 Email: john.edit10@test.com Customer Name, Gender and Date of Birth: unchanged (see TC_NC_001) | G84: High | H84: All six fields show the updated values; Name, Gender and DOB are unchanged | I84: All six fields show the updated values; Name, Gender and DOB are unchanged | J84: Pass | K84: Amjad | L84: Amjad
A85: TC_EC_012 | B85: Update a single field only | C85: Verify updating one field leaves the others unchanged | D85: 1. Logged in as Manager 2. Customer 4073 exists and is associated with this Manager (created in TC_NC_001) 3. Edit Customer page is open | E85: 1. Enter the Customer ID from Test data and click Submit 2. Change the field(s) marked ◄ to the values in Test data 3. Click Submit | F85: Customer ID: 4073 Address: 78 River Road ◄ City: (leave as loaded) State: (leave as loaded) PIN Code: (leave as loaded) Mobile Number: (leave as loaded) Email: (leave as loaded) | G85: Medium | H85: Address is updated; City, State, PIN, Mobile and Email keep their previous values | I85: The address was updated and the other fields kept their previous values; no success message was displayed. | J85: Pass | K85: Amjad | L85: Amjad
...

Sheet RTM
A1: Req ID | B1: SRS section | C1: Module | D1: Requirement | E1: Error | F1: Test cases | G1: No. of TCs | H1: Pass | I1: Fail | J1: Blocked | K1: Coverage status | L1: Linked defects
A2: L1 | B2: 3.3.1 | C2: Login | D2: User ID must not be blank | E2: Display error E1 | F2: TC_LG_002, TC_LG_004 | G2: =SUMPRODUCT(COUNTIF('Test Cases'!$A$2:$A$1513,{"TC_LG_002","TC_LG_004"})) -> 2 | H2: =SUMPRODUCT(COUNTIFS('Test Cases'!$A$2:$A$1513,{"TC_LG_002","TC_LG_004"},'Test Cases'!$J$2:$J$1513,"Pass")) -> 2 | I2: =SUMPRODUCT(COUNTIFS('Test Cases'!$A$2:$A$1513,{"TC_LG_002","TC_LG_004"},'Test Cases'!$J$2:$J$1513,"Fail")) -> 0 | J2: =SUMPRODUCT(COUNTIFS('Test Cases'!$A$2:$A$1513,{"TC_LG_002","TC_LG_004"},'Test Cases'!$J$2:$J$1513,"Blocked")) -> 0 | K2: =IF(G2=0,"Not covered",IF(I2>0,"Fail",IF(J2>0,"Blocked",IF(H2=G2,"Pass","Partially executed")))) -> Pass | L2: -
A3: L2 | B3: 3.3.1 | C3: Login | D3: Password must not be blank | E3: Display error E2 | F3: TC_LG_003 - TC_LG_004 | G3: =SUMPRODUCT(COUNTIF('Test Cases'!$A$2:$A$1513,{"TC_LG_003","TC_LG_004"})) -> 2 | H3: =SUMPRODUCT(COUNTIFS('Test Cases'!$A$2:$A$1513,{"TC_LG_003","TC_LG_004"},'Test Cases'!$J$2:$J$1513,"Pass")) -> 2 | I3: =SUMPRODUCT(COUNTIFS('Test Cases'!$A$2:$A$1513,{"TC_LG_003","TC_LG_004"},'Test Cases'!$J$2:$J$1513,"Fail")) -> 0 | J3: =SUMPRODUCT(COUNTIFS('Test Cases'!$A$2:$A$1513,{"TC_LG_003","TC_LG_004"},'Test Cases'!$J$2:$J$1513,"Blocked")) -> 0 | K3: =IF(G3=0,"Not covered",IF(I3>0,"Fail",IF(J3>0,"Blocked",IF(H3=G3,"Pass","Partially executed")))) -> Pass | L3: -
A4: L3 | B4: 3.3.1 | C4: Login | D4: User ID and Password combination must exist in database | E4: Display error E3 | F4: TC_LG_005 - TC_LG_006 | G4: =SUMPRODUCT(COUNTIF('Test Cases'!$A$2:$A$1513,{"TC_LG_005","TC_LG_006"})) -> 2 | H4: =SUMPRODUCT(COUNTIFS('Test Cases'!$A$2:$A$1513,{"TC_LG_005","TC_LG_006"},'Test Cases'!$J$2:$J$1513,"Pass")) -> 0 | I4: =SUMPRODUCT(COUNTIFS('Test Cases'!$A$2:$A$1513,{"TC_LG_005","TC_LG_006"},'Test Cases'!$J$2:$J$1513,"Fail")) -> 2 | J4: =SUMPRODUCT(COUNTIFS('Test Cases'!$A$2:$A$1513,{"TC_LG_005","TC_LG_006"},'Test Cases'!$J$2:$J$1513,"Blocked")) -> 0 | K4: =IF(G4=0,"Not covered",IF(I4>0,"Fail",IF(J4>0,"Blocked",IF(H4=G4,"Pass","Partially executed")))) -> Fail | L4: BUG_006
A5: L4 | B5: 3.3.1 | C5: Login | D5: Account must not be locked | E5: Display lockout message | F5: TC_LG_010 | G5: =SUMPRODUCT(COUNTIF('Test Cases'!$A$2:$A$1513,{"TC_LG_010"})) -> 1 | H5: =SUMPRODUCT(COUNTIFS('Test Cases'!$A$2:$A$1513,{"TC_LG_010"},'Test Cases'!$J$2:$J$1513,"Pass")) -> 0 | I5: =SUMPRODUCT(COUNTIFS('Test Cases'!$A$2:$A$1513,{"TC_LG_010"},'Test Cases'!$J$2:$J$1513,"Fail")) -> 1 | J5: =SUMPRODUCT(COUNTIFS('Test Cases'!$A$2:$A$1513,{"TC_LG_010"},'Test Cases'!$J$2:$J$1513,"Blocked")) -> 0 | K5: =IF(G5=0,"Not covered",IF(I5>0,"Fail",IF(J5>0,"Blocked",IF(H5=G5,"Pass","Partially executed")))) -> Fail | L5: BUG_003
A6: L5 | B6: 3.3.1 | C6: Login | D6: Maximum 3 failed attempts allowed | E6: Lock account after 3 failures | F6: TC_LG_009 | G6: =SUMPRODUCT(COUNTIF('Test Cases'!$A$2:$A$1513,{"TC_LG_009"})) -> 1 | H6: =SUMPRODUCT(COUNTIFS('Test Cases'!$A$2:$A$1513,{"TC_LG_009"},'Test Cases'!$J$2:$J$1513,"Pass")) -> 0 | I6: =SUMPRODUCT(COUNTIFS('Test Cases'!$A$2:$A$1513,{"TC_LG_009"},'Test Cases'!$J$2:$J$1513,"Fail")) -> 1 | J6: =SUMPRODUCT(COUNTIFS('Test Cases'!$A$2:$A$1513,{"TC_LG_009"},'Test Cases'!$J$2:$J$1513,"Blocked")) -> 0 | K6: =IF(G6=0,"Not covered",IF(I6>0,"Fail",IF(J6>0,"Blocked",IF(H6=G6,"Pass","Partially executed")))) -> Fail | L6: BUG_003
A7: NC1 | B7: 3.3.2 | C7: New Customer | D7: Customer Name: Must not be blank | E7: E4 | F7: TC_NC_006 | G7: =SUMPRODUCT(COUNTIF('Test Cases'!$A$2:$A$1513,{"TC_NC_006"})) -> 1 | H7: =SUMPRODUCT(COUNTIFS('Test Cases'!$A$2:$A$1513,{"TC_NC_006"},'Test Cases'!$J$2:$J$1513,"Pass")) -> 1 | I7: =SUMPRODUCT(COUNTIFS('Test Cases'!$A$2:$A$1513,{"TC_NC_006"},'Test Cases'!$J$2:$J$1513,"Fail")) -> 0 | J7: =SUMPRODUCT(COUNTIFS('Test Cases'!$A$2:$A$1513,{"TC_NC_006"},'Test Cases'!$J$2:$J$1513,"Blocked")) -> 0 | K7: =IF(G7=0,"Not covered",IF(I7>0,"Fail",IF(J7>0,"Blocked",IF(H7=G7,"Pass","Partially executed")))) -> Pass | L7: -
A8: NC2 | B8: 3.3.2 | C8: New Customer | D8: Customer Name: Must not contain numbers | E8: E48 | F8: TC_NC_007 | G8: =SUMPRODUCT(COUNTIF('Test Cases'!$A$2:$A$1513,{"TC_NC_007"})) -> 1 | H8: =SUMPRODUCT(COUNTIFS('Test Cases'!$A$2:$A$1513,{"TC_NC_007"},'Test Cases'!$J$2:$J$1513,"Pass")) -> 1 | I8: =SUMPRODUCT(COUNTIFS('Test Cases'!$A$2:$A$1513,{"TC_NC_007"},'Test Cases'!$J$2:$J$1513,"Fail")) -> 0 | J8: =SUMPRODUCT(COUNTIFS('Test Cases'!$A$2:$A$1513,{"TC_NC_007"},'Test Cases'!$J$2:$J$1513,"Blocked")) -> 0 | K8: =IF(G8=0,"Not covered",IF(I8>0,"Fail",IF(J8>0,"Blocked",IF(H8=G8,"Pass","Partially executed")))) -> Pass | L8: -
A9: NC3 | B9: 3.3.2 | C9: New Customer | D9: Customer Name: Must not contain special characters | E9: E46 | F9: TC_NC_008 | G9: =SUMPRODUCT(COUNTIF('Test Cases'!$A$2:$A$1513,{"TC_NC_008"})) -> 1 | H9: =SUMPRODUCT(COUNTIFS('Test Cases'!$A$2:$A$1513,{"TC_NC_008"},'Test Cases'!$J$2:$J$1513,"Pass")) -> 1 | I9: =SUMPRODUCT(COUNTIFS('Test Cases'!$A$2:$A$1513,{"TC_NC_008"},'Test Cases'!$J$2:$J$1513,"Fail")) -> 0 | J9: =SUMPRODUCT(COUNTIFS('Test Cases'!$A$2:$A$1513,{"TC_NC_008"},'Test Cases'!$J$2:$J$1513,"Blocked")) -> 0 | K9: =IF(G9=0,"Not covered",IF(I9>0,"Fail",IF(J9>0,"Blocked",IF(H9=G9,"Pass","Partially executed")))) -> Pass | L9: -
A10: NC4 | B10: 3.3.2 | C10: New Customer | D10: Customer Name: First character cannot be space | E10: E47 | F10: TC_NC_009 | G10: =SUMPRODUCT(COUNTIF('Test Cases'!$A$2:$A$1513,{"TC_NC_009"})) -> 1 | H10: =SUMPRODUCT(COUNTIFS('Test Cases'!$A$2:$A$1513,{"TC_NC_009"},'Test Cases'!$J$2:$J$1513,"Pass")) -> 1 | I10: =SUMPRODUCT(COUNTIFS('Test Cases'!$A$2:$A$1513,{"TC_NC_009"},'Test Cases'!$J$2:$J$1513,"Fail")) -> 0 | J10: =SUMPRODUCT(COUNTIFS('Test Cases'!$A$2:$A$1513,{"TC_NC_009"},'Test Cases'!$J$2:$J$1513,"Blocked")) -> 0 | K10: =IF(G10=0,"Not covered",IF(I10>0,"Fail",IF(J10>0,"Blocked",IF(H10=G10,"Pass","Partially executed")))) -> Pass | L10: -
A11: NC5 | B11: 3.3.2 | C11: New Customer | D11: Address: Must not be blank | E11: E5 | F11: TC_NC_020 | G11: =SUMPRODUCT(COUNTIF('Test Cases'!$A$2:$A$1513,{"TC_NC_020"})) -> 1 | H11: =SUMPRODUCT(COUNTIFS('Test Cases'!$A$2:$A$1513,{"TC_NC_020"},'Test Cases'!$J$2:$J$1513,"Pass")) -> 1 | I11: =SUMPRODUCT(COUNTIFS('Test Cases'!$A$2:$A$1513,{"TC_NC_020"},'Test Cases'!$J$2:$J$1513,"Fail")) -> 0 | J11: =SUMPRODUCT(COUNTIFS('Test Cases'!$A$2:$A$1513,{"TC_NC_020"},'Test Cases'!$J$2:$J$1513,"Blocked")) -> 0 | K11: =IF(G11=0,"Not covered",IF(I11>0,"Fail",IF(J11>0,"Blocked",IF(H11=G11,"Pass","Partially executed")))) -> Pass | L11: -
A12: NC6 | B12: 3.3.2 | C12: New Customer | D12: City: Must not be blank | E12: E6 | F12: TC_NC_024 | G12: =SUMPRODUCT(COUNTIF('Test Cases'!$A$2:$A$1513,{"TC_NC_024"})) -> 1 | H12: =SUMPRODUCT(COUNTIFS('Test Cases'!$A$2:$A$1513,{"TC_NC_024"},'Test Cases'!$J$2:$J$1513,"Pass")) -> 1 | I12: =SUMPRODUCT(COUNTIFS('Test Cases'!$A$2:$A$1513,{"TC_NC_024"},'Test Cases'!$J$2:$J$1513,"Fail")) -> 0 | J12: =SUMPRODUCT(COUNTIFS('Test Cases'!$A$2:$A$1513,{"TC_NC_024"},'Test Cases'!$J$2:$J$1513,"Blocked")) -> 0 | K12: =IF(G12=0,"Not covered",IF(I12>0,"Fail",IF(J12>0,"Blocked",IF(H12=G12,"Pass","Partially executed")))) -> Pass | L12: -
A13: NC7 | B13: 3.3.2 | C13: New Customer | D13: City: Must not contain numbers | E13: E48 | F13: TC_NC_025 | G13: =SUMPRODUCT(COUNTIF('Test Cases'!$A$2:$A$1513,{"TC_NC_025"})) -> 1 | H13: =SUMPRODUCT(COUNTIFS('Test Cases'!$A$2:$A$1513,{"TC_NC_025"},'Test Cases'!$J$2:$J$1513,"Pass")) -> 1 | I13: =SUMPRODUCT(COUNTIFS('Test Cases'!$A$2:$A$1513,{"TC_NC_025"},'Test Cases'!$J$2:$J$1513,"Fail")) -> 0 | J13: =SUMPRODUCT(COUNTIFS('Test Cases'!$A$2:$A$1513,{"TC_NC_025"},'Test Cases'!$J$2:$J$1513,"Blocked")) -> 0 | K13: =IF(G13=0,"Not covered",IF(I13>0,"Fail",IF(J13>0,"Blocked",IF(H13=G13,"Pass","Partially executed")))) -> Pass | L13: -
A14: NC8 | B14: 3.3.2 | C14: New Customer | D14: State: Must not be blank | E14: E7 | F14: TC_NC_027 | G14: =SUMPRODUCT(COUNTIF('Test Cases'!$A$2:$A$1513,{"TC_NC_027"})) -> 1 | H14: =SUMPRODUCT(COUNTIFS('Test Cases'!$A$2:$A$1513,{"TC_NC_027"},'Test Cases'!$J$2:$J$1513,"Pass")) -> 1 | I14: =SUMPRODUCT(COUNTIFS('Test Cases'!$A$2:$A$1513,{"TC_NC_027"},'Test Cases'!$J$2:$J$1513,"Fail")) -> 0 | J14: =SUMPRODUCT(COUNTIFS('Test Cases'!$A$2:$A$1513,{"TC_NC_027"},'Test Cases'!$J$2:$J$1513,"Blocked")) -> 0 | K14: =IF(G14=0,"Not covered",IF(I14>0,"Fail",IF(J14>0,"Blocked",IF(H14=G14,"Pass","Partially executed")))) -> Pass | L14: -
A15: NC9 | B15: 3.3.2 | C15: New Customer | D15: State: Must not contain numbers | E15: E48 | F15: TC_NC_028 | G15: =SUMPRODUCT(COUNTIF('Test Cases'!$A$2:$A$1513,{"TC_NC_028"})) -> 1 | H15: =SUMPRODUCT(COUNTIFS('Test Cases'!$A$2:$A$1513,{"TC_NC_028"},'Test Cases'!$J$2:$J$1513,"Pass")) -> 1 | I15: =SUMPRODUCT(COUNTIFS('Test Cases'!$A$2:$A$1513,{"TC_NC_028"},'Test Cases'!$J$2:$J$1513,"Fail")) -> 0 | J15: =SUMPRODUCT(COUNTIFS('Test Cases'!$A$2:$A$1513,{"TC_NC_028"},'Test Cases'!$J$2:$J$1513,"Blocked")) -> 0 | K15: =IF(G15=0,"Not covered",IF(I15>0,"Fail",IF(J15>0,"Blocked",IF(H15=G15,"Pass","Partially executed")))) -> Pass | L15: -
A16: NC10 | B16: 3.3.2 | C16: New Customer | D16: PIN Code: Must not be blank | E16: E8 | F16: TC_NC_030 | G16: =SUMPRODUCT(COUNTIF('Test Cases'!$A$2:$A$1513,{"TC_NC_030"})) -> 1 | H16: =SUMPRODUCT(COUNTIFS('Test Cases'!$A$2:$A$1513,{"TC_NC_030"},'Test Cases'!$J$2:$J$1513,"Pass")) -> 1 | I16: =SUMPRODUCT(COUNTIFS('Test Cases'!$A$2:$A$1513,{"TC_NC_030"},'Test Cases'!$J$2:$J$1513,"Fail")) -> 0 | J16: =SUMPRODUCT(COUNTIFS('Test Cases'!$A$2:$A$1513,{"TC_NC_030"},'Test Cases'!$J$2:$J$1513,"Blocked")) -> 0 | K16: =IF(G16=0,"Not covered",IF(I16>0,"Fail",IF(J16>0,"Blocked",IF(H16=G16,"Pass","Partially executed")))) -> Pass | L16: -
A17: NC11 | B17: 3.3.2 | C17: New Customer | D17: PIN Code: Must be numeric | E17: E9 | F17: TC_NC_031 | G17: =SUMPRODUCT(COUNTIF('Test Cases'!$A$2:$A$1513,{"TC_NC_031"})) -> 1 | H17: =SUMPRODUCT(COUNTIFS('Test Cases'!$A$2:$A$1513,{"TC_NC_031"},'Test Cases'!$J$2:$J$1513,"Pass")) -> 1 | I17: =SUMPRODUCT(COUNTIFS('Test Cases'!$A$2:$A$1513,{"TC_NC_031"},'Test Cases'!$J$2:$J$1513,"Fail")) -> 0 | J17: =SUMPRODUCT(COUNTIFS('Test Cases'!$A$2:$A$1513,{"TC_NC_031"},'Test Cases'!$J$2:$J$1513,"Blocked")) -> 0 | K17: =IF(G17=0,"Not covered",IF(I17>0,"Fail",IF(J17>0,"Blocked",IF(H17=G17,"Pass","Partially executed")))) -> Pass | L17: -
A18: NC12 | B18: 3.3.2 | C18: New Customer | D18: PIN Code: Must have exactly 6 digits | E18: E10 | F18: TC_NC_032 | G18: =SUMPRODUCT(COUNTIF('Test Cases'!$A$2:$A$1513,{"TC_NC_032"})) -> 1 | H18: =SUMPRODUCT(COUNTIFS('Test Cases'!$A$2:$A$1513,{"TC_NC_032"},'Test Cases'!$J$2:$J$1513,"Pass")) -> 1 | I18: =SUMPRODUCT(COUNTIFS('Test Cases'!$A$2:$A$1513,{"TC_NC_032"},'Test Cases'!$J$2:$J$1513,"Fail")) -> 0 | J18: =SUMPRODUCT(COUNTIFS('Test Cases'!$A$2:$A$1513,{"TC_NC_032"},'Test Cases'!$J$2:$J$1513,"Blocked")) -> 0 | K18: =IF(G18=0,"Not covered",IF(I18>0,"Fail",IF(J18>0,"Blocked",IF(H18=G18,"Pass","Partially executed")))) -> Pass | L18: -
A19: NC13 | B19: 3.3.2 | C19: New Customer | D19: Mobile Number: Must not be blank | E19: E11 | F19: TC_NC_034 | G19: =SUMPRODUCT(COUNTIF('Test Cases'!$A$2:$A$1513,{"TC_NC_034"})) -> 1 | H19: =SUMPRODUCT(COUNTIFS('Test Cases'!$A$2:$A$1513,{"TC_NC_034"},'Test Cases'!$J$2:$J$1513,"Pass")) -> 1 | I19: =SUMPRODUCT(COUNTIFS('Test Cases'!$A$2:$A$1513,{"TC_NC_034"},'Test Cases'!$J$2:$J$1513,"Fail")) -> 0 | J19: =SUMPRODUCT(COUNTIFS('Test Cases'!$A$2:$A$1513,{"TC_NC_034"},'Test Cases'!$J$2:$J$1513,"Blocked")) -> 0 | K19: =IF(G19=0,"Not covered",IF(I19>0,"Fail",IF(J19>0,"Blocked",IF(H19=G19,"Pass","Partially executed")))) -> Pass | L19: -
A20: NC14 | B20: 3.3.2 | C20: New Customer | D20: Mobile Number: Must be numeric | E20: E12 | F20: TC_NC_035 | G20: =SUMPRODUCT(COUNTIF('Test Cases'!$A$2:$A$1513,{"TC_NC_035"})) -> 1 | H20: =SUMPRODUCT(COUNTIFS('Test Cases'!$A$2:$A$1513,{"TC_NC_035"},'Test Cases'!$J$2:$J$1513,"Pass")) -> 1 | I20: =SUMPRODUCT(COUNTIFS('Test Cases'!$A$2:$A$1513,{"TC_NC_035"},'Test Cases'!$J$2:$J$1513,"Fail")) -> 0 | J20: =SUMPRODUCT(COUNTIFS('Test Cases'!$A$2:$A$1513,{"TC_NC_035"},'Test Cases'!$J$2:$J$1513,"Blocked")) -> 0 | K20: =IF(G20=0,"Not covered",IF(I20>0,"Fail",IF(J20>0,"Blocked",IF(H20=G20,"Pass","Partially executed")))) -> Pass | L20: -
A21: NC15 | B21: 3.3.2 | C21: New Customer | D21: Email: Must not be blank | E21: E13 | F21: TC_NC_038 | G21: =SUMPRODUCT(COUNTIF('Test Cases'!$A$2:$A$1513,{"TC_NC_038"})) -> 1 | H21: =SUMPRODUCT(COUNTIFS('Test Cases'!$A$2:$A$1513,{"TC_NC_038"},'Test Cases'!$J$2:$J$1513,"Pass")) -> 1 | I21: =SUMPRODUCT(COUNTIFS('Test Cases'!$A$2:$A$1513,{"TC_NC_038"},'Test Cases'!$J$2:$J$1513,"Fail")) -> 0 | J21: =SUMPRODUCT(COUNTIFS('Test Cases'!$A$2:$A$1513,{"TC_NC_038"},'Test Cases'!$J$2:$J$1513,"Blocked")) -> 0 | K21: =IF(G21=0,"Not covered",IF(I21>0,"Fail",IF(J21>0,"Blocked",IF(H21=G21,"Pass","Partially executed")))) -> Pass | L21: -
A22: NC16 | B22: 3.3.2 | C22: New Customer | D22: Email: Must be valid email format | E22: E14 | F22: TC_NC_039 | G22: =SUMPRODUCT(COUNTIF('Test Cases'!$A$2:$A$1513,{"TC_NC_039"})) -> 1 | H22: =SUMPRODUCT(COUNTIFS('Test Cases'!$A$2:$A$1513,{"TC_NC_039"},'Test Cases'!$J$2:$J$1513,"Pass")) -> 1 | I22: =SUMPRODUCT(COUNTIFS('Test Cases'!$A$2:$A$1513,{"TC_NC_039"},'Test Cases'!$J$2:$J$1513,"Fail")) -> 0 | J22: =SUMPRODUCT(COUNTIFS('Test Cases'!$A$2:$A$1513,{"TC_NC_039"},'Test Cases'!$J$2:$J$1513,"Blocked")) -> 0 | K22: =IF(G22=0,"Not covered",IF(I22>0,"Fail",IF(J22>0,"Blocked",IF(H22=G22,"Pass","Partially executed")))) -> Pass | L22: -
A23: NC17 | B23: 3.3.2 | C23: New Customer | D23: Email: Must be unique in system | E23: E49 | F23: TC_NC_040 | G23: =SUMPRODUCT(COUNTIF('Test Cases'!$A$2:$A$1513,{"TC_NC_040"})) -> 1 | H23: =SUMPRODUCT(COUNTIFS('Test Cases'!$A$2:$A$1513,{"TC_NC_040"},'Test Cases'!$J$2:$J$1513,"Pass")) -> 1 | I23: =SUMPRODUCT(COUNTIFS('Test Cases'!$A$2:$A$1513,{"TC_NC_040"},'Test Cases'!$J$2:$J$1513,"Fail")) -> 0 | J23: =SUMPRODUCT(COUNTIFS('Test Cases'!$A$2:$A$1513,{"TC_NC_040"},'Test Cases'!$J$2:$J$1513,"Blocked")) -> 0 | K23: =IF(G23=0,"Not covered",IF(I23>0,"Fail",IF(J23>0,"Blocked",IF(H23=G23,"Pass","Partially executed")))) -> Pass | L23: -
A24: NC18 | B24: 3.3.2 | C24: New Customer | D24: Date of Birth: Must not be blank | E24: E50 | F24: TC_NC_014 | G24: =SUMPRODUCT(COUNTIF('Test Cases'!$A$2:$A$1513,{"TC_NC_014"})) -> 1 | H24: =SUMPRODUCT(COUNTIFS('Test Cases'!$A$2:$A$1513,{"TC_NC_014"},'Test Cases'!$J$2:$J$1513,"Pass")) -> 1 | I24: =SUMPRODUCT(COUNTIFS('Test Cases'!$A$2:$A$1513,{"TC_NC_014"},'Test Cases'!$J$2:$J$1513,"Fail")) -> 0 | J24: =SUMPRODUCT(COUNTIFS('Test Cases'!$A$2:$A$1513,{"TC_NC_014"},'Test Cases'!$J$2:$J$1513,"Blocked")) -> 0 | K24: =IF(G24=0,"Not covered",IF(I24>0,"Fail",IF(J24>0,"Blocked",IF(H24=G24,"Pass","Partially executed")))) -> Pass | L24: -
A25: NC19 | B25: 3.3.2 | C25: New Customer | D25: Date of Birth: Age must be 18 or above | E25: Custom error | F25: TC_NC_017 | G25: =SUMPRODUCT(COUNTIF('Test Cases'!$A$2:$A$1513,{"TC_NC_017"})) -> 1 | H25: =SUMPRODUCT(COUNTIFS('Test Cases'!$A$2:$A$1513,{"TC_NC_017"},'Test Cases'!$J$2:$J$1513,"Pass")) -> 0 | I25: =SUMPRODUCT(COUNTIFS('Test Cases'!$A$2:$A$1513,{"TC_NC_017"},'Test Cases'!$J$2:$J$1513,"Fail")) -> 1 | J25: =SUMPRODUCT(COUNTIFS('Test Cases'!$A$2:$A$1513,{"TC_NC_017"},'Test Cases'!$J$2:$J$1513,"Blocked")) -> 0 | K25: =IF(G25=0,"Not covered",IF(I25>0,"Fail",IF(J25>0,"Blocked",IF(H25=G25,"Pass","Partially executed")))) -> Fail | L25: BUG_008
A26: NC20 | B26: 3.3.2 | C26: New Customer | D26: Gender: Must be selected | E26: Custom error | F26: TC_NC_012 | G26: =SUMPRODUCT(COUNTIF('Test Cases'!$A$2:$A$1513,{"TC_NC_012"})) -> 1 | H26: =SUMPRODUCT(COUNTIFS('Test Cases'!$A$2:$A$1513,{"TC_NC_012"},'Test Cases'!$J$2:$J$1513,"Pass")) -> 0 | I26: =SUMPRODUCT(COUNTIFS('Test Cases'!$A$2:$A$1513,{"TC_NC_012"},'Test Cases'!$J$2:$J$1513,"Fail")) -> 1 | J26: =SUMPRODUCT(COUNTIFS('Test Cases'!$A$2:$A$1513,{"TC_NC_012"},'Test Cases'!$J$2:$J$1513,"Blocked")) -> 0 | K26: =IF(G26=0,"Not covered",IF(I26>0,"Fail",IF(J26>0,"Blocked",IF(H26=G26,"Pass","Partially executed")))) -> Fail | L26: BUG_011
A27: EC1 | B27: 3.3.3 | C27: Edit Customer | D27: Customer ID must not be blank | E27: E15 | F27: TC_EC_004 | G27: =SUMPRODUCT(COUNTIF('Test Cases'!$A$2:$A$1513,{"TC_EC_004"})) -> 1 | H27: =SUMPRODUCT(COUNTIFS('Test Cases'!$A$2:$A$1513,{"TC_EC_004"},'Test Cases'!$J$2:$J$1513,"Pass")) -> 1 | I27: =SUMPRODUCT(COUNTIFS('Test Cases'!$A$2:$A$1513,{"TC_EC_004"},'Test Cases'!$J$2:$J$1513,"Fail")) -> 0 | J27: =SUMPRODUCT(COUNTIFS('Test Cases'!$A$2:$A$1513,{"TC_EC_004"},'Test Cases'!$J$2:$J$1513,"Blocked")) -> 0 | K27: =IF(G27=0,"Not covered",IF(I27>0,"Fail",IF(J27>0,"Blocked",IF(H27=G27,"Pass","Partially executed")))) -> Pass | L27: -
A28: EC2 | B28: 3.3.3 | C28: Edit Customer | D28: Customer ID must be numeric | E28: E16 | F28: TC_EC_005 | G28: =SUMPRODUCT(COUNTIF('Test Cases'!$A$2:$A$1513,{"TC_EC_005"})) -> 1 | H28: =SUMPRODUCT(COUNTIFS('Test Cases'!$A$2:$A$1513,{"TC_EC_005"},'Test Cases'!$J$2:$J$1513,"Pass")) -> 1 | I28: =SUMPRODUCT(COUNTIFS('Test Cases'!$A$2:$A$1513,{"TC_EC_005"},'Test Cases'!$J$2:$J$1513,"Fail")) -> 0 | J28: =SUMPRODUCT(COUNTIFS('Test Cases'!$A$2:$A$1513,{"TC_EC_005"},'Test Cases'!$J$2:$J$1513,"Blocked")) -> 0 | K28: =IF(G28=0,"Not covered",IF(I28>0,"Fail",IF(J28>0,"Blocked",IF(H28=G28,"Pass","Partially executed")))) -> Pass | L28: -
A29: EC3 | B29: 3.3.3 | C29: Edit Customer | D29: Customer ID must exist in database | E29: Custom error | F29: TC_EC_007 | G29: =SUMPRODUCT(COUNTIF('Test Cases'!$A$2:$A$1513,{"TC_EC_007"})) -> 1 | H29: =SUMPRODUCT(COUNTIFS('Test Cases'!$A$2:$A$1513,{"TC_EC_007"},'Test Cases'!$J$2:$J$1513,"Pass")) -> 1 | I29: =SUMPRODUCT(COUNTIFS('Test Cases'!$A$2:$A$1513,{"TC_EC_007"},'Test Cases'!$J$2:$J$1513,"Fail")) -> 0 | J29: =SUMPRODUCT(COUNTIFS('Test Cases'!$A$2:$A$1513,{"TC_EC_007"},'Test Cases'!$J$2:$J$1513,"Blocked")) -> 0 | K29: =IF(G29=0,"Not covered",IF(I29>0,"Fail",IF(J29>0,"Blocked",IF(H29=G29,"Pass","Partially executed")))) -> Pass | L29: -
A30: EC4 | B30: 3.3.3 | C30: Edit Customer | D30: Customer must be associated with current manager | E30: E44 | F30: TC_EC_008 | G30: =SUMPRODUCT(COUNTIF('Test Cases'!$A$2:$A$1513,{"TC_EC_008"})) -> 1 | H30: =SUMPRODUCT(COUNTIFS('Test Cases'!$A$2:$A$1513,{"TC_EC_008"},'Test Cases'!$J$2:$J$1513,"Pass")) -> 1 | I30: =SUMPRODUCT(COUNTIFS('Test Cases'!$A$2:$A$1513,{"TC_EC_008"},'Test Cases'!$J$2:$J$1513,"Fail")) -> 0 | J30: =SUMPRODUCT(COUNTIFS('Test Cases'!$A$2:$A$1513,{"TC_EC_008"},'Test Cases'!$J$2:$J$1513,"Blocked")) -> 0 | K30: =IF(G30=0,"Not covered",IF(I30>0,"Fail",IF(J30>0,"Blocked",IF(H30=G30,"Pass","Partially executed")))) -> Pass | L30: -
A31: EC5 | B31: 3.3.3 | C31: Edit Customer | D31: Email must be unique (if changed) | E31: E49 | F31: TC_EC_033 - TC_EC_036 | G31: =SUMPRODUCT(COUNTIF('Test Cases'!$A$2:$A$1513,{"TC_EC_033","TC_EC_034","TC_EC_035","TC_EC_036"})) -> 4 | H31: =SUMPRODUCT(COUNTIFS('Test Cases'!$A$2:$A$1513,{"TC_EC_033","TC_EC_034","TC_EC_035","TC_EC_036"},'Test Cases'!$J$2:$J$1513,"Pass")) -> 0 | I31: =SUMPRODUCT(COUNTIFS('Test Cases'!$A$2:$A$1513,{"TC_EC_033","TC_EC_034","TC_EC_035","TC_EC_036"},'Test Cases'!$J$2:$J$1513,"Fail")) -> 4 | J31: =SUMPRODUCT(COUNTIFS('Test Cases'!$A$2:$A$1513,{"TC_EC_033","TC_EC_034","TC_EC_035","TC_EC_036"},'Test Cases'!$J$2:$J$1513,"Blocked")) -> 0 | K31: =IF(G31=0,"Not covered",IF(I31>0,"Fail",IF(J31>0,"Blocked",IF(H31=G31,"Pass","Partially executed")))) -> Fail | L31: BUG_013, BUG_019
A32: EC6 | B32: 3.3.3 | C32: Edit Customer | D32: All field validations same as New Customer | E32: Various | F32: TC_EC_014 - TC_EC_015, TC_EC_017 - TC_EC_021, TC_EC_023 - TC_EC_025, TC_EC_027 - TC_EC_028, TC_EC_031 - TC_EC_032 | G32: =SUMPRODUCT(COUNTIF('Test Cases'!$A$2:$A$1513,{"TC_EC_014","TC_EC_015","TC_EC_017","TC_EC_018","TC_EC_019","TC_EC_020","TC_EC_021","TC_EC_023","TC_EC_024","TC_EC_025","TC_EC_027","TC_EC_028","TC_EC_031","TC_EC_032"})) -> 14 | H32: =SUMPRODUCT(COUNTIFS('Test Cases'!$A$2:$A$1513,{"TC_EC_014","TC_EC_015","TC_EC_017","TC_EC_018","TC_EC_019","TC_EC_020","TC_EC_021","TC_EC_023","TC_EC_024","TC_EC_025","TC_EC_027","TC_EC_028","TC_EC_031","TC_EC_032"},'Test Cases'!$J$2:$J$1513,"Pass")) -> 0 | I32: =SUMPRODUCT(COUNTIFS('Test Cases'!$A$2:$A$1513,{"TC_EC_014","TC_EC_015","TC_EC_017","TC_EC_018","TC_EC_019","TC_EC_020","TC_EC_021","TC_EC_023","TC_EC_024","TC_EC_025","TC_EC_027","TC_EC_028","TC_EC_031","TC_EC_032"},'Test Cases'!$J$2:$J$1513,"Fail")) -> 14 | J32: =SUMPRODUCT(COUNTIFS('Test Cases'!$A$2:$A$1513,{"TC_EC_014","TC_EC_015","TC_EC_017","TC_EC_018","TC_EC_019","TC_EC_020","TC_EC_021","TC_EC_023","TC_EC_024","TC_EC_025","TC_EC_027","TC_EC_028","TC_EC_031","TC_EC_032"},'Test Cases'!$J$2:$J$1513,"Blocked")) -> 0 | K32: =IF(G32=0,"Not covered",IF(I32>0,"Fail",IF(J32>0,"Blocked",IF(H32=G32,"Pass","Partially executed")))) -> Fail | L32: BUG_014, BUG_015, BUG_016, BUG_017, BUG_018
A33: DC1 | B33: 3.3.4 | C33: Delete Customer | D33: Customer ID must not be blank | E33: E15 | F33: TC_DC_006 | G33: =SUMPRODUCT(COUNTIF('Test Cases'!$A$2:$A$1513,{"TC_DC_006"})) -> 1 | H33: =SUMPRODUCT(COUNTIFS('Test Cases'!$A$2:$A$1513,{"TC_DC_006"},'Test Cases'!$J$2:$J$1513,"Pass")) -> 1 | I33: =SUMPRODUCT(COUNTIFS('Test Cases'!$A$2:$A$1513,{"TC_DC_006"},'Test Cases'!$J$2:$J$1513,"Fail")) -> 0 | J33: =SUMPRODUCT(COUNTIFS('Test Cases'!$A$2:$A$1513,{"TC_DC_006"},'Test Cases'!$J$2:$J$1513,"Blocked")) -> 0 | K33: =IF(G33=0,"Not covered",IF(I33>0,"Fail",IF(J33>0,"Blocked",IF(H33=G33,"Pass","Partially executed")))) -> Pass | L33: -
A34: DC2 | B34: 3.3.4 | C34: Delete Customer | D34: Customer ID must be numeric | E34: E16 | F34: TC_DC_007 | G34: =SUMPRODUCT(COUNTIF('Test Cases'!$A$2:$A$1513,{"TC_DC_007"})) -> 1 | H34: =SUMPRODUCT(COUNTIFS('Test Cases'!$A$2:$A$1513,{"TC_DC_007"},'Test Cases'!$J$2:$J$1513,"Pass")) -> 1 | I34: =SUMPRODUCT(COUNTIFS('Test Cases'!$A$2:$A$1513,{"TC_DC_007"},'Test Cases'!$J$2:$J$1513,"Fail")) -> 0 | J34: =SUMPRODUCT(COUNTIFS('Test Cases'!$A$2:$A$1513,{"TC_DC_007"},'Test Cases'!$J$2:$J$1513,"Blocked")) -> 0 | K34: =IF(G34=0,"Not covered",IF(I34>0,"Fail",IF(J34>0,"Blocked",IF(H34=G34,"Pass","Partially executed")))) -> Pass | L34: -
A35: DC3 | B35: 3.3.4 | C35: Delete Customer | D35: Customer ID must exist in database | E35: Custom error | F35: TC_DC_005, TC_DC_009 | G35: =SUMPRODUCT(COUNTIF('Test Cases'!$A$2:$A$1513,{"TC_DC_005","TC_DC_009"})) -> 2 | H35: =SUMPRODUCT(COUNTIFS('Test Cases'!$A$2:$A$1513,{"TC_DC_005","TC_DC_009"},'Test Cases'!$J$2:$J$1513,"Pass")) -> 2 | I35: =SUMPRODUCT(COUNTIFS('Test Cases'!$A$2:$A$1513,{"TC_DC_005","TC_DC_009"},'Test Cases'!$J$2:$J$1513,"Fail")) -> 0 | J35: =SUMPRODUCT(COUNTIFS('Test Cases'!$A$2:$A$1513,{"TC_DC_005","TC_DC_009"},'Test Cases'!$J$2:$J$1513,"Blocked")) -> 0 | K35: =IF(G35=0,"Not covered",IF(I35>0,"Fail",IF(J35>0,"Blocked",IF(H35=G35,"Pass","Partially executed")))) -> Pass | L35: -
A36: DC4 | B36: 3.3.4 | C36: Delete Customer | D36: Customer must not have any active accounts | E36: Custom error | F36: TC_DC_010 | G36: =SUMPRODUCT(COUNTIF('Test Cases'!$A$2:$A$1513,{"TC_DC_010"})) -> 1 | H36: =SUMPRODUCT(COUNTIFS('Test Cases'!$A$2:$A$1513,{"TC_DC_010"},'Test Cases'!$J$2:$J$1513,"Pass")) -> 1 | I36: =SUMPRODUCT(COUNTIFS('Test Cases'!$A$2:$A$1513,{"TC_DC_010"},'Test Cases'!$J$2:$J$1513,"Fail")) -> 0 | J36: =SUMPRODUCT(COUNTIFS('Test Cases'!$A$2:$A$1513,{"TC_DC_010"},'Test Cases'!$J$2:$J$1513,"Blocked")) -> 0 | K36: =IF(G36=0,"Not covered",IF(I36>0,"Fail",IF(J36>0,"Blocked",IF(H36=G36,"Pass","Partially executed")))) -> Pass | L36: -
A37: DC5 | B37: 3.3.4 | C37: Delete Customer | D37: Customer must be associated with current manager | E37: E44 | F37: TC_DC_011 | G37: =SUMPRODUCT(COUNTIF('Test Cases'!$A$2:$A$1513,{"TC_DC_011"})) -> 1 | H37: =SUMPRODUCT(COUNTIFS('Test Cases'!$A$2:$A$1513,{"TC_DC_011"},'Test Cases'!$J$2:$J$1513,"Pass")) -> 1 | I37: =SUMPRODUCT(COUNTIFS('Test Cases'!$A$2:$A$1513,{"TC_DC_011"},'Test Cases'!$J$2:$J$1513,"Fail")) -> 0 | J37: =SUMPRODUCT(COUNTIFS('Test Cases'!$A$2:$A$1513,{"TC_DC_011"},'Test Cases'!$J$2:$J$1513,"Blocked")) -> 0 | K37: =IF(G37=0,"Not covered",IF(I37>0,"Fail",IF(J37>0,"Blocked",IF(H37=G37,"Pass","Partially executed")))) -> Pass | L37: -
A38: NA1 | B38: 3.3.5 | C38: New Account | D38: Customer ID: Must not be blank | E38: E15 | F38: TC_NA_008 | G38: =SUMPRODUCT(COUNTIF('Test Cases'!$A$2:$A$1513,{"TC_NA_008"})) -> 1 | H38: =SUMPRODUCT(COUNTIFS('Test Cases'!$A$2:$A$1513,{"TC_NA_008"},'Test Cases'!$J$2:$J$1513,"Pass")) -> 1 | I38: =SUMPRODUCT(COUNTIFS('Test Cases'!$A$2:$A$1513,{"TC_NA_008"},'Test Cases'!$J$2:$J$1513,"Fail")) -> 0 | J38: =SUMPRODUCT(COUNTIFS('Test Cases'!$A$2:$A$1513,{"TC_NA_008"},'Test Cases'!$J$2:$J$1513,"Blocked")) -> 0 | K38: =IF(G38=0,"Not covered",IF(I38>0,"Fail",IF(J38>0,"Blocked",IF(H38=G38,"Pass","Partially executed")))) -> Pass | L38: -
A39: NA2 | B39: 3.3.5 | C39: New Account | D39: Customer ID: Must be numeric | E39: E16 | F39: TC_NA_009 | G39: =SUMPRODUCT(COUNTIF('Test Cases'!$A$2:$A$1513,{"TC_NA_009"})) -> 1 | H39: =SUMPRODUCT(COUNTIFS('Test Cases'!$A$2:$A$1513,{"TC_NA_009"},'Test Cases'!$J$2:$J$1513,"Pass")) -> 1 | I39: =SUMPRODUCT(COUNTIFS('Test Cases'!$A$2:$A$1513,{"TC_NA_009"},'Test Cases'!$J$2:$J$1513,"Fail")) -> 0 | J39: =SUMPRODUCT(COUNTIFS('Test Cases'!$A$2:$A$1513,{"TC_NA_009"},'Test Cases'!$J$2:$J$1513,"Blocked")) -> 0 | K39: =IF(G39=0,"Not covered",IF(I39>0,"Fail",IF(J39>0,"Blocked",IF(H39=G39,"Pass","Partially executed")))) -> Pass | L39: -
A40: NA3 | B40: 3.3.5 | C40: New Account | D40: Customer ID: Must exist in database | E40: Custom error | F40: TC_NA_011 | G40: =SUMPRODUCT(COUNTIF('Test Cases'!$A$2:$A$1513,{"TC_NA_011"})) -> 1 | H40: =SUMPRODUCT(COUNTIFS('Test Cases'!$A$2:$A$1513,{"TC_NA_011"},'Test Cases'!$J$2:$J$1513,"Pass")) -> 1 | I40: =SUMPRODUCT(COUNTIFS('Test Cases'!$A$2:$A$1513,{"TC_NA_011"},'Test Cases'!$J$2:$J$1513,"Fail")) -> 0 | J40: =SUMPRODUCT(COUNTIFS('Test Cases'!$A$2:$A$1513,{"TC_NA_011"},'Test Cases'!$J$2:$J$1513,"Blocked")) -> 0 | K40: =IF(G40=0,"Not covered",IF(I40>0,"Fail",IF(J40>0,"Blocked",IF(H40=G40,"Pass","Partially executed")))) -> Pass | L40: -
...

Sheet Bug Report
A1: ID | B1: Summary | C1: Description | D1: Pre-Condition | E1: Environment | F1: Steps | G1: Expected result | H1: Actual result | I1: Severity | J1: Priority | K1: Status | L1: Test data | M1: Created by | N1: Assigned to | O1: Test case ID | P1: Comment
A2: BUG_001 | B2: [Login] SQL injection input bypasses the login (authentication bypass) | C2: The login form accepts a SQL injection string as the User ID and logs the user in. Authentication can be bypassed, which exposes every Manager function. | D2: Login page is open | E2: Google Chrome; Guru99 Bank demo site (V2) - https://demo.guru99.com/V4/ | F2: 1. Open the Login page 2. Enter ' OR '1'='1 in User ID 3. Enter x in Password 4. Click Login | G2: The login is rejected (E3) and no access is granted. | H2: The system accepted the login and redirected the manager to the dashboard. | I2: Critical | J2: High | K2: Open | L2: User ID: ' OR '1'='1 Password: x | M2: Amjad | N2: Development Team | O2: TC_LG_014 (1 failed, 0 blocked)
A3: BUG_002 | B3: [Login] Protected pages can be opened directly without logging in | C3: A protected internal page opens when its URL is entered directly while the user is not logged in. Access control (SRS RBAC) is not enforced. | D3: User is not logged in; the URL of an internal page is known | E3: Google Chrome; Guru99 Bank demo site (V2) - https://demo.guru99.com/V4/ | F3: 1. Make sure no user is logged in 2. Enter the URL of an internal page directly in the browser | G3: The user is redirected to the Login page. | H3: The system opened the protected page directly without any authentication. | I3: Critical | J3: High | K3: Open | L3: Direct URL of an internal page | M3: Amjad | N3: Development Team | O3: TC_LG_018 (1 failed, 0 blocked)
A4: BUG_003 | B4: [Login] Account is not locked after 3 failed login attempts | C4: The SRS requires the account to be locked after 3 consecutive failed logins (L4, L5). The system never locks the account, so passwords can be guessed without limit. | D4: Manager account is active and not locked | E4: Google Chrome; Guru99 Bank demo site (V2) - https://demo.guru99.com/V4/ | F4: 1. Open the Login page 2. Enter a valid User ID and a wrong Password, click Login 3. Repeat step 2 two more times 4. Log in with the valid User ID and Password | G4: Attempts 1 and 2 show E3. After attempt 3 the account is locked and E55 is displayed; the valid login is rejected. | H4: The account was not locked after the 3 failed attempts and the lockout message (E55) was not displayed. | I4: High | J4: High | K4: Open | L4: User ID: mngr668217 Password: wrongpas (3 attempts), then rUqyzUv | M4: Amjad | N4: Development Team | O4: TC_LG_009 - TC_LG_010 (2 failed, 0 blocked) | P4: Test data of TC_LG_009 was corrected to use a wrong password. Please re-run TC_LG_009 and TC_LG_010 to confirm the result.
A5: BUG_004 | B5: [Login] Session is not terminated after Logout (Back button returns to the dashboard) | C5: After logging out, the browser Back button returns to the protected dashboard. The session stays usable after Logout. | D5: User is logged in | E5: Google Chrome; Guru99 Bank demo site (V2) - https://demo.guru99.com/V4/ | F5: 1. Log in as a Manager 2. Click Logout 3. Click the browser Back button | G5: The user cannot return to a protected page without logging in again. | H5: The session was not terminated: after pressing the Back button, the manager could return to the dashboard. | I5: High | J5: High | K5: Open | L5: User ID: mngr668217 | M5: Amjad | N5: Development Team | O5: TC_LG_017 (1 failed, 0 blocked)
A6: BUG_005 | B6: [Login] User ID and Password are not case-sensitive | C6: The login accepts the User ID in uppercase and the Password with different letter casing. The SRS requires case-sensitive credentials; this weakens password security. | D6: Manager account "mngr668217" exists with password "rUqyzUv" | E6: Google Chrome; Guru99 Bank demo site (V2) - https://demo.guru99.com/V4/ | F6: 1. Open the Login page 2. Enter the User ID MNGR668217 and the correct Password, click Login 3. Enter the correct User ID and the Password RUQYZUV, click Login | G6: E3 is displayed and the login is rejected in both cases. | H6: The system accepted both logins and redirected the manager to the dashboard. | I6: Medium | J6: Medium | K6: Open | L6: User ID: MNGR668217 / Password: rUqyzUv User ID: mngr668217 / Password: RUQYZUV | M6: Amjad | N6: Development Team | O6: TC_LG_007 - TC_LG_008 (2 failed, 0 blocked)
A7: BUG_006 | B7: [Login] Invalid login shows "User is not valid" instead of the SRS message E3 | C7: For an unknown User ID or a wrong Password the system shows an alert with different wording from the message defined in the SRS. | D7: Login page is open | E7: Google Chrome; Guru99 Bank demo site (V2) - https://demo.guru99.com/V4/ | F7: 1. Open the Login page 2. Enter an invalid User ID or a wrong Password 3. Click Login | G7: E3: "User ID and Password do not match" is displayed. | H7: The alert "User is not valid" was displayed and the login was rejected. | I7: Low | J7: Low | K7: Open | L7: User ID: ghost999 / Password: Pass@123 User ID: mngr668217 / Password: wrongpas | M7: Amjad | N7: Development Team | O7: TC_LG_005 - TC_LG_006 (2 failed, 0 blocked)
A8: BUG_007 | B8: [Login] Login field length limits differ from the SRS (User ID max 10, Password unlimited) | C8: The SRS defines a maximum of 30 characters for User ID and Password. The User ID field accepts only 10 characters and the Password field has no limit. | D8: Login page is open | E8: Google Chrome; Guru99 Bank demo site (V2) - https://demo.guru99.com/V4/ | F8: 1. Open the Login page 2. Type 30 characters in User ID and in Password 3. Type 31 characters in both fields | G8: 30 characters are accepted; the 31st character is rejected or truncated. | H8: The User ID field accepts a maximum of 10 characters and the Password field has no maximum length limit. | I8: Medium | J8: Low | K8: Open | L8: 30-character and 31-character strings | M8: Amjad | N8: Development Team | O8: TC_LG_013 (1 failed, 0 blocked)
A9: BUG_008 | B9: [New Customer] No age validation: customers under 18 and a future date of birth are accepted | C9: The SRS requires customers to be 18 or older (E58). The form creates customers aged 17, aged 10 and with a future date of birth without any error. | D9: Logged in as a Manager New Customer page is open | E9: Google Chrome; Guru99 Bank demo site (V2) - https://demo.guru99.com/V4/ | F9: 1. Open New Customer 2. Fill all fields with valid data and set the Date of Birth to a date that makes the customer under 18 (or a future date) 3. Click Submit | G9: E58 "Age must be 18 years or above" is displayed and no customer is created. | H9: Customers were created with Customer IDs 52817 (17 years old), 27595 (10 years old) and 69229 (future date of birth); no error message was displayed. | I9: High | J9: High | K9: Open | L9: Date of Birth: (Execution date - 18 years) + 1 day; Execution date - 10 years; tomorrow | M9: Amjad | N9: Development Team | O9: TC_NC_016 - TC_NC_018 (3 failed, 0 blocked)
A10: BUG_009 | B10: [New Customer] Mobile number length is not validated (9 and 11 digits are accepted) | C10: E59 requires a 10-digit mobile number, but customers are created with 9-digit and 11-digit numbers. | D10: Logged in as a Manager New Customer page is open | E10: Google Chrome; Guru99 Bank demo site (V2) - https://demo.guru99.com/V4/ | F10: 1. Open New Customer 2. Fill all fields with valid data and enter a 9-digit (or 11-digit) Mobile Number 3. Click Submit | G10: E59 "Mobile number must be 10 digits" is displayed and no customer is created. | H10: Customers were created with IDs 33471 (9 digits) and 78251 (11 digits); no error message was displayed. | I10: Medium | J10: Medium | K10: Open | L10: Mobile Number: 555123456; 55512345678 | M10: Amjad | N10: Development Team | O10: TC_NC_036 - TC_NC_037 (2 failed, 0 blocked)
A11: BUG_010 | B11: [New Customer] Password rules are not enforced (5-character and 31-character passwords accepted) | C11: The SRS defines a password of 6 to 30 characters. A 5-character password and a 31-character password are accepted. | D11: Logged in as a Manager New Customer page is open | E11: Google Chrome; Guru99 Bank demo site (V2) - https://demo.guru99.com/V4/ | F11: 1. Open New Customer 2. Fill all fields with valid data and enter a 5-character (or 31-character) Password 3. Click Submit | G11: The password is rejected with an error and no customer is created. | H11: A customer was created with a 5-character password (Customer ID 790); the 30-character and 31-character passwords were both accepted. | I11: Medium | J11: Medium | K11: Open | L11: Password: Ab@12; 31 characters | M11: Amjad | N11: Development Team | O11: TC_NC_044, TC_NC_046 (2 failed, 0 blocked)
